Workbook

Sheet Simulation 1
A6: Dynamic Cap Table & Dilution Dashboard - Assumptions
A8: General Assumptions
A9: Starting Shares Outstanding | B9: 2500
A10: ESOP Pool % | B10: 0
A11: Currency | B11: USD
A12: Round 1 Year | B12: 2026
A13: Round 2 Year | B13: 2027
A14: Round 3 Year | B14: 2028
A16: Funding Rounds
A17: Round | B17: Year | C17: Pre-Money Valuation ($) | D17: Investment Amount ($) | E17: Post-Money Valuation ($) | F17: Round Dilution % | G17: Share Price ($)
A18: Round 1 | B18: 2026 | C18: ='[1]Valuation - DCF'!$F$87 -> 0 | D18: 740213 | E18: =C18+D18 -> 740213 | F18: =IFERROR(D18/E18,0) -> 1 | G18: =IFERROR(C18/'Simulation 1'!$N$38,0) -> 0
A19: Round 2 | B19: 2027 | C19: =E18 -> 740213 | D19: 1000000 | E19: =C19+D19 -> 1740213 | F19: =IFERROR(D19/E19,0) -> 0.5746423 | G19: =IFERROR(C19/'Simulation 1'!$N$52,0) -> 296.0852
A20: Round 3 | B20: 2028 | E20: =C20+D20 -> 0 | F20: =IFERROR(D20/E20,0) -> 0 | G20: =IFERROR(C20/'Simulation 1'!N53,0) -> 0
A22: Current Cap Table
A24: Investor Name | B24: Current Ownership | C24: Initial Shares | D24: 2026 Ownership | E24: 2026 Shares | F24: 2027 Ownership | G24: 2027 Shares | H24: Total Shares
A25: K Group Holding | B25: 0.8 | C25: =B25*'Simulation 1'!$B$9 -> 2000 | D25: ='Simulation 1'!J38 -> 0.8 | E25: ='Simulation 1'!I38 -> 2000 | F25: ='Simulation 1'!J52 -> 0.8 | G25: ='Simulation 1'!I52 -> 4701.925 | H25: =C25 -> 2000
A26: Joseph Sioufi | B26: 0.07 | C26: =B26*'Simulation 1'!$B$9 -> 175 | D26: ='Simulation 1'!J39 -> 0.07 | E26: ='Simulation 1'!I39 -> 175 | F26: ='Simulation 1'!J53 -> 0.07 | G26: ='Simulation 1'!I53 -> 411.41844 | H26: =C26 -> 175
A27: Jihad Bakradon | B27: 0.07 | C27: =B27*'Simulation 1'!$B$9 -> 175 | D27: ='Simulation 1'!J40 -> 0.07 | E27: ='Simulation 1'!I40 -> 175 | F27: ='Simulation 1'!J54 -> 0.07 | G27: ='Simulation 1'!I54 -> 411.41844 | H27: =C27 -> 175
A28: Rsheid Khazen | B28: 0.02 | C28: =B28*'Simulation 1'!$B$9 -> 50 | D28: ='Simulation 1'!J41 -> 0.02 | E28: ='Simulation 1'!I41 -> 50 | F28: ='Simulation 1'!J55 -> 0.02 | G28: ='Simulation 1'!I55 -> 117.54812 | H28: =C28 -> 50
A29: Dany Germanos | B29: 0.02 | C29: =B29*'Simulation 1'!$B$9 -> 50 | D29: ='Simulation 1'!J42 -> 0.02 | E29: ='Simulation 1'!I42 -> 50 | F29: ='Simulation 1'!J56 -> 0.02 | G29: ='Simulation 1'!I56 -> 117.54812 | H29: =C29 -> 50
A30: Saleh Khazen | B30: 0.02 | C30: =B30*'Simulation 1'!$B$9 -> 50 | D30: ='Simulation 1'!J43 -> 0.02 | E30: ='Simulation 1'!I43 -> 50 | F30: ='Simulation 1'!J57 -> 0.02 | G30: ='Simulation 1'!I57 -> 117.54812 | H30: =C30 -> 50
A31: Total | B31: =SUM(B25:B30) -> 1 | C31: =SUM(C25:C30) -> 2500 | D31: =SUM(D25:D30) -> 1 | E31: =SUM(E25:E30) -> 2500 | F31: =SUM(F25:F30) -> 1 | G31: =SUM(G25:G30) -> 5877.4062 | H31: =SUM(H25:H30) -> 2500
A34: Dilution Engine - Participation & Share-Based Dilution
A36: Round 1 / 2026
A37: Investor | B37: Opening Shares | C37: Opening Ownership | D37: Participates? | E37: Required Pro-Rata Investment | F37: Auto-Allocated Contribution | G37: New Shares Purchased | H37: Dilution % | I37: Ending Shares | J37: Ending Ownership | K37: Total Shares | M37: Round 1 Summary | N37: Value
A38: K Group Holding | B38: ='Simulation 1'!C25 -> 2000 | C38: =B38/$N$38 -> 0.8 | D38: Yes | E38: =C38*'Simulation 1'!$D$18 -> 592170.4 | F38: =IF(OR(D38<>"Yes",'Simulation 1'!$D$18=0,SUMIF($D$38:$D$43,"Yes",$B$38:$B$43)=0),0,'Simulation 1'!$D$18*B38/SUMIF($D$38:$D$43,"Yes",$B$38:$B$43)) -> 592170.4 | G38: =IFERROR(F38/'Simulation 1'!$G$18,0) -> 0 | H38: =C38-J38 -> 0 | I38: =B38+G38 -> 2000 | J38: =IFERROR(I38/SUM($I$38:$I$43),0) -> 0.8 | M38: Opening Total Shares | N38: =SUM($B$38:$B$43) -> 2500
A39: Joseph Sioufi | B39: ='Simulation 1'!C26 -> 175 | C39: =B39/$N$38 -> 0.07 | D39: Yes | E39: =C39*'Simulation 1'!$D$18 -> 51814.91 | F39: =IF(OR(D39<>"Yes",'Simulation 1'!$D$18=0,SUMIF($D$38:$D$43,"Yes",$B$38:$B$43)=0),0,'Simulation 1'!$D$18*B39/SUMIF($D$38:$D$43,"Yes",$B$38:$B$43)) -> 51814.91 | G39: =IFERROR(F39/'Simulation 1'!$G$18,0) -> 0 | H39: =C39-J39 -> 0 | I39: =B39+G39 -> 175 | J39: =IFERROR(I39/SUM($I$38:$I$43),0) -> 0.07 | M39: Ending Total Shares | N39: =SUM($I$38:$I$43) -> 2500
A40: Jihad Pakradon | B40: ='Simulation 1'!C27 -> 175 | C40: =B40/$N$38 -> 0.07 | D40: Yes | E40: =C40*'Simulation 1'!$D$18 -> 51814.91 | F40: =IF(OR(D40<>"Yes",'Simulation 1'!$D$18=0,SUMIF($D$38:$D$43,"Yes",$B$38:$B$43)=0),0,'Simulation 1'!$D$18*B40/SUMIF($D$38:$D$43,"Yes",$B$38:$B$43)) -> 51814.91 | G40: =IFERROR(F40/'Simulation 1'!$G$18,0) -> 0 | H40: =C40-J40 -> 0 | I40: =B40+G40 -> 175 | J40: =IFERROR(I40/SUM($I$38:$I$43),0) -> 0.07 | M40: New Shares Issued | N40: =SUM($G$38:$G$43) -> 0
A41: Rsheid Khazen | B41: ='Simulation 1'!C28 -> 50 | C41: =B41/$N$38 -> 0.02 | D41: Yes | E41: =C41*'Simulation 1'!$D$18 -> 14804.26 | F41: =IF(OR(D41<>"Yes",'Simulation 1'!$D$18=0,SUMIF($D$38:$D$43,"Yes",$B$38:$B$43)=0),0,'Simulation 1'!$D$18*B41/SUMIF($D$38:$D$43,"Yes",$B$38:$B$43)) -> 14804.26 | G41: =IFERROR(F41/'Simulation 1'!$G$18,0) -> 0 | H41: =C41-J41 -> 0 | I41: =B41+G41 -> 50 | J41: =IFERROR(I41/SUM($I$38:$I$43),0) -> 0.02
A42: Dany Germanos | B42: ='Simulation 1'!C29 -> 50 | C42: =B42/$N$38 -> 0.02 | D42: Yes | E42: =C42*'Simulation 1'!$D$18 -> 14804.26 | F42: =IF(OR(D42<>"Yes",'Simulation 1'!$D$18=0,SUMIF($D$38:$D$43,"Yes",$B$38:$B$43)=0),0,'Simulation 1'!$D$18*B42/SUMIF($D$38:$D$43,"Yes",$B$38:$B$43)) -> 14804.26 | G42: =IFERROR(F42/'Simulation 1'!$G$18,0) -> 0 | H42: =C42-J42 -> 0 | I42: =B42+G42 -> 50 | J42: =IFERROR(I42/SUM($I$38:$I$43),0) -> 0.02
A43: Saleh Khazen | B43: ='Simulation 1'!C30 -> 50 | C43: =B43/$N$38 -> 0.02 | D43: Yes | E43: =C43*'Simulation 1'!$D$18 -> 14804.26 | F43: =IF(OR(D43<>"Yes",'Simulation 1'!$D$18=0,SUMIF($D$38:$D$43,"Yes",$B$38:$B$43)=0),0,'Simulation 1'!$D$18*B43/SUMIF($D$38:$D$43,"Yes",$B$38:$B$43)) -> 14804.26 | G43: =IFERROR(F43/'Simulation 1'!$G$18,0) -> 0 | H43: =C43-J43 -> 0 | I43: =B43+G43 -> 50 | J43: =IFERROR(I43/SUM($I$38:$I$43),0) -> 0.02
A50: Round 2 / 2027
A51: Investor | B51: Opening Shares | C51: Opening Ownership | D51: Participates? | E51: Required Pro-Rata Investment | F51: Auto-Allocated Contribution | G51: New Shares Purchased | H51: Dilution % | I51: Ending Shares | J51: Ending Ownership | K51: Total Shares | M51: Round 2 Summary | N51: Value
A52: K Group Holding | B52: =I38 -> 2000 | C52: =IFERROR(B52/SUM($B$52:$B$57),0) -> 0.8 | D52: Yes | E52: =C52*'Simulation 1'!$D$19 -> 800000 | F52: =IF(OR(D52<>"Yes",'Simulation 1'!$D$19=0,SUMIF($D$52:$D$57,"Yes",$B$52:$B$57)=0),0,'Simulation 1'!$D$19*B52/SUMIF($D$52:$D$57,"Yes",$B$52:$B$57)) -> 800000 | G52: =IFERROR(F52/'Simulation 1'!$G$19,0) -> 2701.925 | H52: =C52-J52 -> 0 | I52: =B52+G52 -> 4701.925 | J52: =IFERROR(I52/SUM($I$52:$I$57),0) -> 0.8 | M52: Opening Total Shares | N52: =SUM($B$52:$B$57) -> 2500
A53: Joseph Sioufi | B53: =I39 -> 175 | C53: =IFERROR(B53/SUM($B$52:$B$57),0) -> 0.07 | D53: Yes | E53: =C53*'Simulation 1'!$D$19 -> 70000 | F53: =IF(OR(D53<>"Yes",'Simulation 1'!$D$19=0,SUMIF($D$52:$D$57,"Yes",$B$52:$B$57)=0),0,'Simulation 1'!$D$19*B53/SUMIF($D$52:$D$57,"Yes",$B$52:$B$57)) -> 70000 | G53: =IFERROR(F53/'Simulation 1'!$G$19,0) -> 236.41844 | H53: =C53-J53 -> 0 | I53: =B53+G53 -> 411.41844 | J53: =IFERROR(I53/SUM($I$52:$I$57),0) -> 0.07 | M53: Ending Total Shares | N53: =SUM($I$52:$I$57) -> 5877.4062
A54: Jihad Pakradon | B54: =I40 -> 175 | C54: =IFERROR(B54/SUM($B$52:$B$57),0) -> 0.07 | D54: Yes | E54: =C54*'Simulation 1'!$D$19 -> 70000 | F54: =IF(OR(D54<>"Yes",'Simulation 1'!$D$19=0,SUMIF($D$52:$D$57,"Yes",$B$52:$B$57)=0),0,'Simulation 1'!$D$19*B54/SUMIF($D$52:$D$57,"Yes",$B$52:$B$57)) -> 70000 | G54: =IFERROR(F54/'Simulation 1'!$G$19,0) -> 236.41844 | H54: =C54-J54 -> 0 | I54: =B54+G54 -> 411.41844 | J54: =IFERROR(I54/SUM($I$52:$I$57),0) -> 0.07 | M54: New Shares Issued | N54: =SUM($G$52:$G$57) -> 3377.4062
A55: Rsheid Khazen | B55: =I41 -> 50 | C55: =IFERROR(B55/SUM($B$52:$B$57),0) -> 0.02 | D55: Yes | E55: =C55*'Simulation 1'!$D$19 -> 20000 | F55: =IF(OR(D55<>"Yes",'Simulation 1'!$D$19=0,SUMIF($D$52:$D$57,"Yes",$B$52:$B$57)=0),0,'Simulation 1'!$D$19*B55/SUMIF($D$52:$D$57,"Yes",$B$52:$B$57)) -> 20000 | G55: =IFERROR(F55/'Simulation 1'!$G$19,0) -> 67.548125 | H55: =C55-J55 -> 0 | I55: =B55+G55 -> 117.54812 | J55: =IFERROR(I55/SUM($I$52:$I$57),0) -> 0.02
A56: Dany Germanos | B56: =I42 -> 50 | C56: =IFERROR(B56/SUM($B$52:$B$57),0) -> 0.02 | D56: Yes | E56: =C56*'Simulation 1'!$D$19 -> 20000 | F56: =IF(OR(D56<>"Yes",'Simulation 1'!$D$19=0,SUMIF($D$52:$D$57,"Yes",$B$52:$B$57)=0),0,'Simulation 1'!$D$19*B56/SUMIF($D$52:$D$57,"Yes",$B$52:$B$57)) -> 20000 | G56: =IFERROR(F56/'Simulation 1'!$G$19,0) -> 67.548125 | H56: =C56-J56 -> 0 | I56: =B56+G56 -> 117.54812 | J56: =IFERROR(I56/SUM($I$52:$I$57),0) -> 0.02
A57: Saleh Khazen | B57: =I43 -> 50 | C57: =IFERROR(B57/SUM($B$52:$B$57),0) -> 0.02 | D57: Yes | E57: =C57*'Simulation 1'!$D$19 -> 20000 | F57: =IF(OR(D57<>"Yes",'Simulation 1'!$D$19=0,SUMIF($D$52:$D$57,"Yes",$B$52:$B$57)=0),0,'Simulation 1'!$D$19*B57/SUMIF($D$52:$D$57,"Yes",$B$52:$B$57)) -> 20000 | G57: =IFERROR(F57/'Simulation 1'!$G$19,0) -> 67.548125 | H57: =C57-J57 -> 0 | I57: =B57+G57 -> 117.54812 | J57: =IFERROR(I57/SUM($I$52:$I$57),0) -> 0.02
A61: Investor Dilution & Cap Table Dashboard
...

Sheet Options 1-3
A1: Option 1- Valuation is considered 5M & The 500K is given to an external party
A3: Company Valuation (Pre-money) | B3: 5000000 | J3: Check Total Investment | K3: =SUM(E8:E14) -> 750000
A4: Required Investment | B4: 750000
A5: Shares | B5: 2500
A7: Shareholder | B7: Current Shares | C7: Current % | D7: Required Investment | E7: Actual Investment | F7: New Shares Issued | G7: Total Shares After Round | H7: New Ownership % | J7: Price per Existing Share | K7: =B3/SUM(B8:B14) -> 2000
A8: K Group Holding | B8: =$B$5*C8 -> 2000 | C8: 0.8 | D8: =C8*$B$4 -> 600000 | E8: 100000 | F8: =IF($B$4=0,0,E8/($B$3/SUM($B$8:$B$14))) -> 50 | G8: =B8+F8 -> 2050 | H8: =G8/SUM($G$8:$G$14) -> 0.71304348 | J8: Post-money Valuation | K8: =B3+B4 -> 5750000
A9: Joseph Sioufi | B9: =$B$5*C9 -> 175 | C9: 0.07 | D9: =C9*$B$4 -> 52500 | E9: =D9 -> 52500 | F9: =IF($B$4=0,0,E9/($B$3/SUM($B$8:$B$14))) -> 26.25 | G9: =B9+F9 -> 201.25 | H9: =G9/SUM($G$8:$G$14) -> 0.07 | J9: Total New Shares Issued | K9: =SUM(F8:F14) -> 375
A10: Jihad Pakradon | B10: =$B$5*C10 -> 175 | C10: 0.07 | D10: =C10*$B$4 -> 52500 | E10: =D10 -> 52500 | F10: =IF($B$4=0,0,E10/($B$3/SUM($B$8:$B$14))) -> 26.25 | G10: =B10+F10 -> 201.25 | H10: =G10/SUM($G$8:$G$14) -> 0.07 | J10: Total Shares After Round | K10: =SUM(G8:G14) -> 2875
A11: Rsheid Khazen | B11: =$B$5*C11 -> 50 | C11: 0.02 | D11: =C11*$B$4 -> 15000 | E11: =D11 -> 15000 | F11: =IF($B$4=0,0,E11/($B$3/SUM($B$8:$B$14))) -> 7.5 | G11: =B11+F11 -> 57.5 | H11: =G11/SUM($G$8:$G$14) -> 0.02
A12: Dany Germanos | B12: =$B$5*C12 -> 50 | C12: 0.02 | D12: =C12*$B$4 -> 15000 | E12: =D12 -> 15000 | F12: =IF($B$4=0,0,E12/($B$3/SUM($B$8:$B$14))) -> 7.5 | G12: =B12+F12 -> 57.5 | H12: =G12/SUM($G$8:$G$14) -> 0.02
A13: Saleh Khazen | B13: =$B$5*C13 -> 50 | C13: 0.02 | D13: =C13*$B$4 -> 15000 | E13: =D13 -> 15000 | F13: =IF($B$4=0,0,E13/($B$3/SUM($B$8:$B$14))) -> 7.5 | G13: =B13+F13 -> 57.5 | H13: =G13/SUM($G$8:$G$14) -> 0.02
A14: External Party | B14: 0 | C14: 0 | D14: =C14*$B$4 -> 0 | E14: =B4-SUM(E8:E13) -> 500000 | F14: =IF($B$4=0,0,E14/($B$3/SUM($B$8:$B$14))) -> 250 | G14: =B14+F14 -> 250 | H14: =G14/SUM($G$8:$G$14) -> 0.086956522
A16: Total
A18: Option 2 - Valuation is considered 6M & the 500K is given to an external party
A20: Company Valuation (Pre-money) | B20: 6000000 | J20: Check Total Investment | K20: =SUM(E25:E31) -> 750000
A21: Required Investment | B21: =B4 -> 750000
A22: Shares | B22: 2500
A24: Shareholder | B24: Current Shares | C24: Current % | D24: Required Investment | E24: Actual Investment | F24: New Shares Issued | G24: Total Shares After Round | H24: New Ownership % | J24: Price per Existing Share | K24: =B20/SUM(B25:B31) -> 2400
A25: K Group Holding | B25: =$B$22*C25 -> 2000 | C25: 0.8 | D25: =C25*$B$4 -> 600000 | E25: 100000 | F25: =IF($B$21=0,0,E25/($B$20/SUM($B$25:$B$31))) -> 41.666667 | G25: =B25+F25 -> 2041.6667 | H25: =G25/SUM($G$25:$G$31) -> 0.72592593 | J25: Post-money Valuation | K25: =B20+B21 -> 6750000
A26: Joseph Sioufi | B26: =$B$5*C26 -> 175 | C26: 0.07 | D26: =C26*$B$4 -> 52500 | E26: =D26 -> 52500 | F26: =IF($B$21=0,0,E26/($B$20/SUM($B$25:$B$31))) -> 21.875 | G26: =B26+F26 -> 196.875 | H26: =G26/SUM($G$25:$G$31) -> 0.07 | J26: Total New Shares Issued | K26: =SUM(F25:F31) -> 312.5
A27: Jihad Bakradon | B27: =$B$5*C27 -> 175 | C27: 0.07 | D27: =C27*$B$4 -> 52500 | E27: =D27 -> 52500 | F27: =IF($B$21=0,0,E27/($B$20/SUM($B$25:$B$31))) -> 21.875 | G27: =B27+F27 -> 196.875 | H27: =G27/SUM($G$25:$G$31) -> 0.07 | J27: Total Shares After Round | K27: =SUM(G25:G31) -> 2812.5
A28: Rsheid Khazen | B28: =$B$5*C28 -> 50 | C28: 0.02 | D28: =C28*$B$4 -> 15000 | E28: =D28 -> 15000 | F28: =IF($B$21=0,0,E28/($B$20/SUM($B$25:$B$31))) -> 6.25 | G28: =B28+F28 -> 56.25 | H28: =G28/SUM($G$25:$G$31) -> 0.02
A29: Dany Germanos | B29: =$B$5*C29 -> 50 | C29: 0.02 | D29: =C29*$B$4 -> 15000 | E29: =D29 -> 15000 | F29: =IF($B$21=0,0,E29/($B$20/SUM($B$25:$B$31))) -> 6.25 | G29: =B29+F29 -> 56.25 | H29: =G29/SUM($G$25:$G$31) -> 0.02
A30: Saleh Khazen | B30: =$B$5*C30 -> 50 | C30: 0.02 | D30: =C30*$B$4 -> 15000 | E30: =D30 -> 15000 | F30: =IF($B$21=0,0,E30/($B$20/SUM($B$25:$B$31))) -> 6.25 | G30: =B30+F30 -> 56.25 | H30: =G30/SUM($G$25:$G$31) -> 0.02
A31: External Party | B31: 0 | C31: 0 | D31: =C31*$B$4 -> 0 | E31: =B21-SUM(E25:E30) -> 500000 | F31: =IF($B$21=0,0,E31/($B$20/SUM($B$25:$B$31))) -> 208.33333 | G31: =B31+F31 -> 208.33333 | H31: =G31/SUM($G$25:$G$31) -> 0.074074074
H33: =SUM(H25:H31) -> 1
A34: Option 3 - Valuation is considered 6M & the 500K is distributed among current shareholders as per their current shares
A36: Company Valuation (Pre-money) | B36: 6000000
A37: Required Investment | B37: 750000
A38: Shares | B38: 2500
A40: Shareholder | B40: Current Shares | C40: Current % | D40: Required Investment | E40: Actual Investment | F40: New Shares Issued | G40: Total Shares After Round | H40: New Ownership % | J40: When the 500 K is distributed fairly
A41: K Group Holding | B41: =$B$5*C41 -> 2000 | C41: 0.8 | D41: =C41*$B$4 -> 600000 | E41: 100000 | F41: =IF($B$4=0,0,E41/($B$3/SUM($B$8:$B$14))) -> 50 | G41: =B41+F41 -> 2050 | H41: =G41/SUM($G$8:$G$14) -> 0.71304348 | J41: among Investors cause K Group is investing in 100.
A42: Joseph Sioufi | B42: =$B$5*C42 -> 175 | C42: 0.07 | D42: =C42*$B$4 -> 52500 | E42: =D42+K42 -> 227500 | F42: =IF($B$4=0,0,E42/($B$3/SUM($B$8:$B$14))) -> 113.75 | G42: =B42+F42 -> 288.75 | H42: =G42/SUM($G$8:$G$14) -> 0.10043478 | J42: =C9/20% -> 0.35 | K42: =J42*$E$14 -> 175000
A43: Jihad Pakradon | B43: =$B$5*C43 -> 175 | C43: 0.07 | D43: =C43*$B$4 -> 52500 | E43: =D43+K43 -> 227500 | F43: =IF($B$4=0,0,E43/($B$3/SUM($B$8:$B$14))) -> 113.75 | G43: =B43+F43 -> 288.75 | H43: =G43/SUM($G$8:$G$14) -> 0.10043478 | J43: =C10/20% -> 0.35 | K43: =J43*$E$14 -> 175000
A44: Rsheid Khazen | B44: =$B$5*C44 -> 50 | C44: 0.02 | D44: =C44*$B$4 -> 15000 | E44: =D44+K44 -> 65000 | F44: =IF($B$4=0,0,E44/($B$3/SUM($B$8:$B$14))) -> 32.5 | G44: =B44+F44 -> 82.5 | H44: =G44/SUM($G$8:$G$14) -> 0.028695652 | J44: =C11/20% -> 0.1 | K44: =J44*$E$14 -> 50000
A45: Dany Germanos | B45: =$B$5*C45 -> 50 | C45: 0.02 | D45: =C45*$B$4 -> 15000 | E45: =D45+K45 -> 65000 | F45: =IF($B$4=0,0,E45/($B$3/SUM($B$8:$B$14))) -> 32.5 | G45: =B45+F45 -> 82.5 | H45: =G45/SUM($G$8:$G$14) -> 0.028695652 | J45: =C12/20% -> 0.1 | K45: =J45*$E$14 -> 50000
A46: Saleh Khazen | B46: =$B$5*C46 -> 50 | C46: 0.02 | D46: =C46*$B$4 -> 15000 | E46: =D46+K46 -> 65000 | F46: =IF($B$4=0,0,E46/($B$3/SUM($B$8:$B$14))) -> 32.5 | G46: =B46+F46 -> 82.5 | H46: =G46/SUM($G$8:$G$14) -> 0.028695652 | J46: =C13/20% -> 0.1 | K46: =J46*$E$14 -> 50000
A48: Total

Sheet Dashboard
A1: Option 4 - Pro-Rata + Oversubscription Cap Table Model as per the willingness of each investor to invest
A3: Company Valuation (Pre-money) | B3: 6200000 | D3: Round Check
A4: Required Investment Round | B4: 750000 | D4: Total Existing Actual Investment | E4: =SUM(E13:E18) -> 250000
A5: Existing Shares | B5: 2500 | D5: External Investor Fill | E5: =MAX(0,$B$4-E4) -> 500000
A6: Post-money Valuation | B6: =B3+B4 -> 6950000 | D6: Total Investment Check | E6: =E4+E5 -> 750000
A7: Price per Existing Share | B7: =B3/B5 -> 2480 | D7: Over / (Under) Funding | E7: =E6-$B$4 -> 0
A8: Total New Shares Issued | B8: =B4/B7 -> 302.41935 | D8: Total Existing Shortfall | E8: =SUM(G13:G18) -> 500000
A9: Total Shares After Round | B9: =B5+B8 -> 2802.4194 | D9: Total Eligible Excess | E9: =SUM(I13:I18) -> 0
A12: Shareholder | B12: Current Shares | C12: Current % | D12: Pro-rata Investment | E12: Actual Investment | F12: Pro-rata Shares | G12: Shortfall Investment | H12: Oversubscribe? | I12: Excess Investment | J12: Excess Allocation % | K12: New Shares Issued | L12: Total Shares After Round | M12: New Ownership % | N12: Change vs Current %
A13: K Group Holding | B13: 2000 | C13: =B13/$B$5 -> 0.8 | D13: =C13*$B$4 -> 600000 | E13: 100000 | F13: =D13/$B$7 -> 241.93548 | G13: =MAX(0,D13-E13) -> 500000 | H13: No | I13: =IF(H13="Yes",MAX(0,E13-D13),0) -> 0 | J13: =IF($E$9=0,0,I13/$E$9) -> 0 | K13: =E13/$B$7 -> 40.322581 | L13: =B13+K13 -> 2040.3226 | M13: =L13/$B$9 -> 0.72805755 | N13: =M13-C13 -> -0.071942446
A14: Joseph Sioufi | B14: 175 | C14: =B14/$B$5 -> 0.07 | D14: =C14*$B$4 -> 52500 | E14: =D14 -> 52500 | F14: =D14/$B$7 -> 21.169355 | G14: =MAX(0,D14-E14) -> 0 | H14: No | I14: =IF(H14="Yes",MAX(0,E14-D14),0) -> 0 | J14: =IF($E$9=0,0,I14/$E$9) -> 0 | K14: =E14/$B$7 -> 21.169355 | L14: =B14+K14 -> 196.16935 | M14: =L14/$B$9 -> 0.07 | N14: =M14-C14 -> 0
A15: Jihad Pakradon | B15: 175 | C15: =B15/$B$5 -> 0.07 | D15: =C15*$B$4 -> 52500 | E15: =D15 -> 52500 | F15: =D15/$B$7 -> 21.169355 | G15: =MAX(0,D15-E15) -> 0 | H15: No | I15: =IF(H15="Yes",MAX(0,E15-D15),0) -> 0 | J15: =IF($E$9=0,0,I15/$E$9) -> 0 | K15: =E15/$B$7 -> 21.169355 | L15: =B15+K15 -> 196.16935 | M15: =L15/$B$9 -> 0.07 | N15: =M15-C15 -> 0
A16: Rshied Khazen | B16: 50 | C16: =B16/$B$5 -> 0.02 | D16: =C16*$B$4 -> 15000 | E16: =D16 -> 15000 | F16: =D16/$B$7 -> 6.0483871 | G16: =MAX(0,D16-E16) -> 0 | H16: No | I16: =IF(H16="Yes",MAX(0,E16-D16),0) -> 0 | J16: =IF($E$9=0,0,I16/$E$9) -> 0 | K16: =E16/$B$7 -> 6.0483871 | L16: =B16+K16 -> 56.048387 | M16: =L16/$B$9 -> 0.02 | N16: =M16-C16 -> 0
A17: Dany Germanos | B17: 50 | C17: =B17/$B$5 -> 0.02 | D17: =C17*$B$4 -> 15000 | E17: =D17 -> 15000 | F17: =D17/$B$7 -> 6.0483871 | G17: =MAX(0,D17-E17) -> 0 | H17: No | I17: =IF(H17="Yes",MAX(0,E17-D17),0) -> 0 | J17: =IF($E$9=0,0,I17/$E$9) -> 0 | K17: =E17/$B$7 -> 6.0483871 | L17: =B17+K17 -> 56.048387 | M17: =L17/$B$9 -> 0.02 | N17: =M17-C17 -> 0
A18: Saleh Khazen | B18: 50 | C18: =B18/$B$5 -> 0.02 | D18: =C18*$B$4 -> 15000 | E18: =D18 -> 15000 | F18: =D18/$B$7 -> 6.0483871 | G18: =MAX(0,D18-E18) -> 0 | H18: No | I18: =IF(H18="Yes",MAX(0,E18-D18),0) -> 0 | J18: =IF($E$9=0,0,I18/$E$9) -> 0 | K18: =E18/$B$7 -> 6.0483871 | L18: =B18+K18 -> 56.048387 | M18: =L18/$B$9 -> 0.02 | N18: =M18-C18 -> 0
A19: External Party (auto-fill) | B19: 0 | C19: =B19/$B$5 -> 0 | D19: =0 -> 0 | E19: =MAX(0,$B$4-SUM(E13:E18)) -> 500000 | F19: =0 -> 0 | G19: =0 -> 0 | H19: Auto | I19: =0 -> 0 | J19: =0 -> 0 | K19: =E19/$B$7 -> 201.6129 | L19: =B19+K19 -> 201.6129 | M19: =L19/$B$9 -> 0.071942446 | N19: =M19-C19 -> 0.071942446
A21: Total | B21: =SUM(B13:B19) -> 2500 | C21: =SUM(C13:C19) -> 1 | D21: =SUM(D13:D19) -> 750000 | E21: =SUM(E13:E19) -> 750000 | F21: =SUM(F13:F19) -> 302.41935 | G21: =SUM(G13:G19) -> 500000 | I21: =SUM(I13:I19) -> 0 | J21: =SUM(J13:J19) -> 0 | K21: =SUM(K13:K19) -> 302.41935 | L21: =SUM(L13:L19) -> 2802.4194 | M21: =SUM(M13:M19) -> 1 | N21: =SUM(N13:N19) -> -1.110223e-16
A23: Key logic: shares are issued at the fixed pre-money price per share. Existing investors may enter any Actual Investment amount. Any remaining required investment is automatically filled by External Party.
A25: Formula | B25: Meaning | C25: Excel Logic | D25: Comment
A26: Price per share | B26: Pre-money valuation divided by existing shares | C26: =Pre-money / Existing Shares -> #NAME? | D26: Uses fixed pre-money price
A27: New shares issued | B27: Actual investment divided by price per share | C27: =Actual Investment / Price per Share -> #NAME? | D27: This drives ownership increase
A28: Final ownership | B28: Final shares divided by total post-round shares | C28: =Final Shares / Total Shares After Round -> #NAME? | D28: The denominator changes after the round
A29: External fill | B29: Amount not covered by existing shareholders | C29: =MAX(0, Required Round - SUM(Existing Actual Investments)) -> #NAME? | D29: Set to zero when existing investors cover full round
A32: How to Use This Model
A34: Step | B34: What to do | C34: Why it matters | D34: Example
A35: 1 | B35: Change Pre-money, Required Investment, and Existing Shares in yellow cells. | C35: These define price per share and total dilution. | D35: $5.0m pre-money; $750k round
A36: 2 | B36: Enter each existing investor Actual Investment in the yellow input column. | C36: The model calculates new shares from actual cash paid. | D36: Joseph = $262,500
A37: 3 | B37: Set Oversubscribe? to Yes for investors allowed to buy more than pro-rata. | C37: This flags the excess participation pool for analysis. | D37: Joseph = Yes
A38: 4 | B38: External Party is automatic. | C38: It fills any amount not covered by current investors. | D38: If existing investors cover full $750k, external = zero
A39: 5 | B39: Read New Ownership % and Change vs Current %. | C39: These are the actual economic outputs. | D39: Joseph becomes about 10.65% if he invests $262,500
A41: Important | B41: Ownership does not increase linearly with investment. | C41: The total share denominator changes after the financing round. | D41: A 5x pro-rata investment does not equal exactly +4 percentage points.
